<!DOCTYPE html>
<html lang="en">

<head>
    <meta charset="UTF-8">
    <meta http-equiv="X-UA-Compatible" content="IE=edge">
    <meta name="viewport" content="width=device-width, initial-scale=1.0">
    <title>Promise</title>
</head>

</html>
<script>
    // 1. p2的状态 变成了p1
    // let p1 = new Promise((resolve, reject) => {
    //     setTimeout(() => {
    //         reject('456')
    //     }, 3000);
    // })

    // let p2 = new Promise((resolve, reject) => {
    //     setTimeout(() => {
    //         resolve(p1)
    //     }, 1000);
    // })

    // p2.then(success => {
    //     console.log(success);
    // }, err => {
    //     console.log('err', err);
    // }).catch(aa => {
    //     console.log('catch', aa);
    // })
    // err, 456
    // p2的状态变成了p1  那么就走then 第二个回调 ，catch因为之前有人解决了这个状态 那么catch就不走了


    // 2. resolve 或者reject后面的代码还是会执行
    // new Promise((resolve, reject) => {
    //     resolve(1);
    //     console.log(2);
    // }).then(r => {
    //     console.log(r);
    // });

    // 2  1    resolve 在当前脚本所有同步任务执行完才会执行  


    // 3. 解决上个例子 情况
    //  new Promise((resolve, reject) => {
    //     return resolve(1);
    //      // 后面的语句不会执行
    //     console.log(2);
    // }).then(r => {
    //     console.log(r);
    // });
    // 1



    // 4. 返回一个promsie的情况
    // new Promise((resolve, reject) => {
    //     setTimeout(() => {
    //         reject('123')
    //     }, 2000);
    // }).then(fill => { }, err => {
    //     return new Promise((resolve, reject) => {
    //         resolve(err)
    //     });
    // }).then(a => {
    //     console.log('a', a);
    // }, b => {
    //     console.log('b', b);
    // })
    // 两秒钟之后输出 a 123
    // 每个then都是拿到上一个then返回的结果，如果返回的是promise那么就等待他的状态，


    // 5. 继上一个例子不写return的情况
    // new Promise((resolve, reject) => {
    //     setTimeout(() => {
    //         reject('123')
    //     }, 2000);
    // }).then(fill => { }, err => {
    //     new Promise((resolve, reject) => {
    //         reject(err)
    //     });
    // }).then(a => {
    //     console.log('a', a);
    // }, b => {
    //     console.log('b', b);
    // })
    // a,undefined
    // Uncaught (in promise) 123



    // 6. 如果状态是成功 没有处理(没有写then) 默认不会报错
    // new Promise(resolve=>{
    //     resolve('success')
    // })



    // 7. 如果状态是失败 没有处理(没有写then或者catch) 默认会报错
    // new Promise((resolve, reject)=>{
    //     reject('error')
    // })
    //Uncaught (in promise) error



    // 8. 例子
    // new Promise((resolve, reject)=>{
    //     resolve('123')
    // }).then(resolve=>{
    //        return resolve
    // }).then(resolve=>{
    //     console.log(resolve);
    // })
    // //123
    // 返回的是普通的值 那么就一直走第一个




    // 9. catch 使用情况
    // new Promise((resolve, reject) => {
    //     reject('123')
    // }).then(resolve => {
    //     return resolve
    // }).catch(err => {
    //     console.log('err1', err);
    // }).then(resolve => {
    //     console.log(resolve);
    // }).catch(err => {
    //     console.log('err2', err);
    // })
    // err1 123
    // undefined
    // 如果有catch 处理了这个错误 那么后方的catch就不会在处理了 紧接着走下一个then
    // 上一个promise什么都没有返回 那么 下一个then就是undefined catch返回的也是要给promise



    // 10. catch的使用
    // new Promise((resolve, reject) => {
    //     resolve(123)
    // }).then(resolve => {
    //     throw new Error(resolve)
    // }, reject => {
    //     console.log('reject', reject);
    // }).catch(a => console.log(a))
    // Error 123


    // 11. promise处理与不处理的情况
    // new Promise((resolve, reject) => {
    //     resolve('123')
    // }).then(fill => {
    //     return new Promise((resolve, reject) => {
    //         setTimeout(() => {
    //             reject(fill)
    //         }, 1000)
    //     }).then(a => { }, b => {
    //         console.log('b', b);
    //     })
    // }).then(resolve => {
    //     console.log('resolve', resolve);
    // }).catch(error => {
    //     console.log('error', error);
    // })
    // b 123
    // resolve undefined
    // 如果返回的promsie里面的状态自己处理了 ,那么接下来的then就不处理了


    // 11. 没有返回值的情况 注意了
    // new Promise((resolve, reject) => {
    //     reject('123')
    // }).then(resolve => {
    //     setTimeout(() => {
    //         return new Promise(resolve => {
    //             resolve('123')
    //         })
    //     }, 1000);
    // },reject=>{
    //    new Promise((resolve,reject)=>{
    //        setTimeout(() => {
    //           reject('456')
    //        }, 2000);
    //    })
    // }).then(resolve => {
    //     console.log('a', resolve);
    // }).catch(error=>{
    //     console.log('catch',error);
    // })
    // a, undefined   Uncaught (in promise) 456 




    // 11. then处理与没有处理的情况
    // new Promise((resolve, reject) => {
    //     resolve('123')
    // }).then(a=>{}).then().then(resolve => {
    //     console.log(resolve);
    // }).catch(a => console.log(a))
    // 123  为什么不是undefined  因为第一个then和第二个then都没有处理




    // 12. then默认是成功的
    // new Promise((resolve, reject) => {
    //     reject('失败')
    // }).then().catch(error => {
    //     return error
    // }).then(a => {
    //     console.log('a', a);
    // }, b => {
    //     console.log('b', b);
    // })
    // a,失败
    // then 默认是成功




    // 13-14-15下面这个例子      
    // 两种写法的区别  then(a=>{},b=>{}) 与 then(a=>{}).catch()
    // const p1 = new Promise((resolve, reject) => {
    //     resolve('123')
    // })
    // p1.then(a => {
    //    return Promise.reject('555')
    // },b=>{
    //     console.log('b',b);
    // })
    // then 第一个回调抛出的错误 后续没有处理所以   Uncaught (in promise) 555

    // 14.
    // const p2 = new Promise((resolve, reject) => {
    //     reject('456')
    // })
    // p2.then(a => {
    //     return Promise.reject('555')
    // }).catch(error=>{
    //     console.log('error',error);
    // })

    // catch 捕捉了 reject('456') 这个错误



    // 15. catch连续 问题
    // const p3 = new Promise((resolve, reject) => {
    //     reject('456')
    // })
    // p3.then(fill => {
    //     return Promise.reject('555')
    // },err=>{
    //     return Promise.reject(err)
    // }).catch(error=>{
    //     console.log('error',error);
    //     return Promise.reject('失败')
    // }).catch(error2=>{
    //     console.log("error2",error2);
    // }).then(success=>{
    //     console.log('success',success);
    // })
    // error 456
    // error2 失败
    // success undefined
    // 第一个catch捕捉了then中第二个回调 紧接着catch又返回一个错误 那么下方的catch又会捕捉到  
    // 如果 第一个then第二个回调函数err返回的是 Promise.resolve('success') 那么输出 success success



    // 16. promise体内状态改变与否 then的输出问题
    // const promise = new Promise(function (resolve, reject) {
    //     return 666
    // });
    // promise.then(a=>{
    //     console.log('a',a);
    // }).catch(error=> {
    //     console.log(error);
    // });
    // 因为状态没有改变 那么不会有任何输出



    // 17. promise体内出现错误的问题
    // const promise = new Promise((resolve, reject)=> {
    //     // throw new Error('err')
    //     // a+1
    //     //resolve(a+1)
    // });
    // promise.then(a => {
    //     console.log('a', a);
    // }).catch(error => {
    //     console.log('错误',error);
    // });

    // 1.如果是自定义抛出错误 throw new Error('err') then第二个回调和catch都可以捕获
    // 2.如果是promise体内发成错误 a+1  ReferenceError: a is not defined
    // 3.如果是promise体内发成错误 resolve(a+1)  ReferenceError: a is not defined



    // 18. catch捕获的范围更广
    // const promise = new Promise((resolve, reject)=> {
    //   resolve('132')
    // });
    // promise.then(a => {
    //     console.log('a', ab);
    // }).catch(error => {
    //     console.log('错误',error);
    // });
    // catch不仅可以捕获promise函数体内的错误 也可以捕获then里面的错误
    // '错误',ab is not defined 


    // 19. then处理与不处理的问题
    // Promise.resolve('成功').then(a=>{},b=>{}).then().then(fill=>{
    //     console.log(fill);          //undefined
    // })
    // Promise.resolve('成功').then().then().then(fill=>{
    //     console.log(fill);          //成功
    // })

    // 第一个promise的then处理了这个状态 那么后方的then就是对上一个then返回值做处理 返回是undefined
    // 第二个promise的then因为没有处理这个状态 那么后方的then就会处理 所以是 成功


    // 20- 21- 22 
    // 20. 状态一经改变无法回退
    // const promise = new Promise((resolve, reject) => {
    //     throw new Error('test')
    //     resolve('ok');
    //     // setTimeout(() => {
    //     //     throw new Error('test')
    //     // }, 2000)
    // });
    // promise.then(value => {
    //     console.log(value)
    // }).catch(error => {
    //     console.log('error', error);
    // });
    // error Error: test 状态一经改变 无法回退


    // 21.
    // const promise = new Promise((resolve, reject) => {
    //     throw new Error('tests')
    //     setTimeout(() => {
    //         resolve('ok');
    //     }, 2000)
    // });
    // promise.then(value => {
    //     console.log(value)
    // }).catch(error => {
    //     console.log('error', error);
    // });
    // //error Error: tests  因为setTimeout改变了状态 promise已经结束了



    // 23.
    // const promise = new Promise((resolve, reject) => {
    //     resolve('ok');
    //     setTimeout(() => {
    //         throw new Error('tests')
    //         // Promise.reject('456').catch()
    //     }, 2000)
    // });
    // promise.then(value => {
    //     console.log(value)
    // }).catch(error => {
    //     console.log('error', error);
    // });

    // ok Uncaught Error: tests  因为promise已经结束了 所以抛出错误没有捕捉



    // 24. 案列
    // const someAsyncThing = function () {
    //     return new Promise(function (resolve, reject) {
    //         // 下面一行会报错，因为x没有声明
    //         resolve(x + 2);
    //     });
    // };
    // someAsyncThing().then(function () {
    //     return someOtherAsyncThinga();
    // }).catch(function (error) {
    //     console.log('oh no', error);
    //     // 下面一行会报错，因为 y 没有声明
    //     y + 2;
    // }).then(function () {
    //     console.log('carry on');
    // }).catch(error => {
    //     console.log('error', error);
    // })
    // oh no ReferenceError: x is not defined
    // error ReferenceError: y is not defined



    // 25.
    // cosnt p = Promise.all([p1,p2,p3]) 
    // p的状态由p1、p2、p3决定，分成两种情况。
    // (1)只有p1、p2、p3的状态都变成fulfilled，p的状态才会变成fulfilled，此时p1、p2、p3的返回值组成一个数组，传递给p的回调函数。
    // (2)只要p1、p2、p3之中有一个被rejected，p的状态就变成rejected，此时第一个被reject的实例的返回值，会传递给p的回调函数。
    // 总结 全部成功才调用回调   有一个失败就失败 
    // 注意，如果作为参数的 Promise 实例，自己定义了catch方法，那么它一旦被rejected，并不会触发Promise.all()的catch方法。
    // const p1 = new Promise((resolve, reject) => {
    //     resolve('hello');
    // })
    //     .then(result => result)
    //     .catch(e => e);

    // const p2 = new Promise((resolve, reject) => {
    //     throw new Error('报错了');
    // })
    //     .then(result => result)
    //     .catch(e => console.log(e));

    // Promise.all([p1, p2])
    //     .then(result => console.log(result))
    //     .catch(e => console.log(e.message));
    // Error: 报错了
    // ['hello',undefined]
    // 因为p2处理了自己的错误 所以Promise.all走的是then  详细的参考阮一峰 promise.all
    // 如果 p2没有处理自己的错误 那么Promise.all走的是catch




    // 26.
    // // cosnt p = Promise.rice([p1,p2,p3]) 
    // 上面代码中，只要p1、p2、p3之中有一个实例率先改变状态，p的状态就跟着改变。
    // 那个率先改变的 Promise 实例的返回值，就传递给p的回调函数。
    // const p = Promise.race([
    //     fetch('/resource-that-may-take-a-while'),
    //     new Promise(function (resolve, reject) {
    //         setTimeout(() => reject(new Error('request timeout')), 5000)
    //     })
    // ]);
    // p.then(console.log).catch(console.error);
    // 上面代码中，如果 5 秒之内fetch方法无法返回结果，变量p的状态就会变为rejected，从而触发catch方法指定的回调函数。




    // 27.
    // Promise.allSettled()方法接受一个数组作为参数，数组的每个成员都是一个 Promise 对象并返回一个新的 Promise 对象。
    // 只有等到参数数组的所有 Promise 对象都发生状态变更（不管是fulfilled还是rejected),返回的 Promise 对象才会发生状态变更。
    // cosnt p = Promise.allSettled([p1,p2,p3]) 
    // p1 p2 p3 状态都改变了 p的状态才能改变     //而且状态只可能是fulfilled
    // (async _ => {
    //     const promises = [Promise.reject(1), Promise.reject(2), Promise.resolve(3), Promise.resolve(4)]
    //     let result = await Promise.allSettled(promises)

    //     result = result.filter(item => {
    //         return item.status === 'rejected'
    //     })
    //     console.log(result);
    // })()
    // 0: {status: 'rejected', reason: 1}
    // 1: {status: 'rejected', reason: 2}



    // 28.
    // cosnt p = Promise.any([p1,p2,p3]) 
    // 只要参数实例有一个变成fulfilled状态，包装实例就会变成fulfilled状态；
    // 如果所有参数实例都变成rejected状态，包装实例就会变成rejected状态。
    // var resolved = Promise.resolve(42);
    // var rejected = Promise.reject(-1);
    // var alsoRejected = Promise.reject(Infinity);

    // Promise.any([resolved, rejected, alsoRejected]).then(function (result) {
    //     console.log(result); // 42
    // })
    // Promise.any([rejected, alsoRejected]).catch(function (results) {
    //     console.log(results); // [-1, Infinity]  返回的不是一般的error对象 而是一个封装类
    // });


    // 29.
    // Promise.prototype.finally()   //finally不接受任何参数  与状态无关
    // Promise.reject('456').then().catch(err=>{
    //     console.log('err',err);
    // }).finally(()=>{
    //     console.log('fin');
    // })
    // err, 456
    // fin




    // 30.
    // Promise.resolve();
    // 有时候需要将现有对象转为 Promise 对象，Promise.resolve()方法就起到这个作用  参数分为四种情况
    // （1）参数是一个 Promise 实例
    // 如果参数是 Promise 实例，那么Promise.resolve将不做任何修改、原封不动地返回这个实例。
    // （2）参数是一个thenable对象
    // thenable对象指的是具有then方法的对象，比如下面这个对象。
    // （3）参数不是具有then()方法的对象，或根本就不是对象
    // 如果参数是一个原始值，或者是一个不具有then()方法的对象，则Promise.resolve()方法返回一个新的 Promise 对象，状态为resolved。
    // (4) 不带有任何参数
    // Promise.resolve()方法允许调用时不带参数，直接返回一个resolved状态的 Promise 对象。
    // 所以，如果希望得到一个 Promise 对象，比较方便的方法就是直接调用Promise.resolve()方法。




    // 31. 参数是一个Promise实例 那么原封不动的返回这个实例
    // const p1 = new Promise((resolve, reject) => {
    //     reject('123')
    // })
    // Promise.resolve(p1).then(resolve => {
    //     console.log('resolve', resolve);
    // }).catch(err => {
    //     console.log('err', err);
    // })
    // err 123



    // 32. 参数是一个thenable对象
    // let thenable = {
    //     then(resolve, reject) {
    //         resolve(42);
    //     }
    // };
    // let p1 = Promise.resolve(thenable);
    // p1.then(function (value) {
    //     console.log(value);  // 42
    // });




    // 33.
    // 如果参数是一个原始值，或者是一个不具有then()方法的对象，则Promise.resolve()方法返回一个新的 Promise 对象，状态为resolved。
    // Promise.resolve('hello').then(e=>console.log(e))            //hello



    // 34.
    // 需要注意的是，立即resolve()的 Promise 对象，是在本轮“事件循环”（event loop）的结束时执行，而不是在下一轮“事件循环”的开始时。




    // 34. 不带有任何参数
    // Promise.resolve()方法允许调用时不带参数，直接返回一个resolved状态的 Promise 对象。
    // const p = Promise.resolve();
    // p.then(function (e) {
    //     console.log(e);     //undefined
    // });




    // 35.
    // 小插曲  不写await 什么情况
    // 不写 await promise的状态一直是pending 后方代码也瞬间执行
    // 如果有 await 到这里是个异步变成了同步 那么线程到这里就会等待 只有它有结果了 后方代码才会执行
    // 这个例子到了p1这里 等待了三秒后方的代码才执行

    // const promise = () => {
    //     return new Promise((resolve, reject) => {
    //         setTimeout(() => {
    //             resolve('成功了')
    //         }, 3000)
    //     })
    // }
    // (async function () {
    //     console.log(123);
    //     const p1 = await promise();
    //     console.log(p1);
    //     console.log(456);
    // })()




    // 36. Promise.reject()
    // Promise.reject(reason)方法也会返回一个新的 Promise 实例，该实例的状态为rejected。
    // Promise.reject().catch(e=>console.log(e))           //undefined
    //console.log(123456);
    
    // 123456
    // undefined



    // 37-38 暂时没发现这样写的优势  暂存
    // 37. Promise.resolve().then()是本轮事件的末尾执行的
    // const f = () => console.log('now');
    // Promise.resolve().then(f);
    // console.log('next');
    // next
    // now




    // 38.
    // const f = () => console.log('now');
    // (
    //     () => new Promise(
    //         resolve => resolve(f())
    //     )
    // )();
    // console.log('next');
    // now
    // next




    // 30. promise 异步加载图片
    // function loadingIMg(path) {
    //     return new Promise((resolve, reject) => {
    //         const image = new Image()
    //         image.onload = () => {
    //             resolve(image)
    //         }
    //         image.onerror = () => {
    //             reject('错误')
    //         }
    //         image.src = path
    //         document.body.appendChild(image)
    //     })
    // }
    // (async function () {
    //     try {
    //         const image = await loadingIMg('./vue.png')
    //         let width = 10;
    //         let height = 10;

    //         setInterval(() => {
    //             width += 1;
    //             height += 1;
    //             image.style.width = width + 'px';
    //             image.style.height = height + 'px';
    //         },10);
    //     } catch (e) {
    //         console.log(e);
    //     }
    // })()


</script>